2024-03-20 10:14:09,141 ERROR: Exception on /api/blog/posts [POST] [in app.py:828]
Traceback (most recent call last):
  File "/Users/chriswest/Desktop/ai_donkeys/.venv/lib/python3.11/site-packages/flask/app.py", line 1463, in wsgi_app
    response = self.full_dispatch_request()
               ^^^^^^^^^^^^^^^^^^^^^^^^^^^^
  File "/Users/chriswest/Desktop/ai_donkeys/.venv/lib/python3.11/site-packages/flask/app.py", line 872, in full_dispatch_request
    rv = self.handle_user_exception(e)
         ^^^^^^^^^^^^^^^^^^^^^^^^^^^^^
  File "/Users/chriswest/Desktop/ai_donkeys/.venv/lib/python3.11/site-packages/flask_cors/extension.py", line 176, in wrapped_function
    return cors_after_request(app.make_response(f(*args, **kwargs)))
                                                ^^^^^^^^^^^^^^^^^^
  File "/Users/chriswest/Desktop/ai_donkeys/.venv/lib/python3.11/site-packages/flask/app.py", line 870, in full_dispatch_request
    rv = self.dispatch_request()
         ^^^^^^^^^^^^^^^^^^^^^^^
  File "/Users/chriswest/Desktop/ai_donkeys/.venv/lib/python3.11/site-packages/flask/app.py", line 855, in dispatch_request
    return self.ensure_sync(self.view_functions[rule.endpoint])(**view_args)  # type: ignore[no-any-return]
           ^^^^^^^^^^^^^^^^^^^^^^^^^^^^^^^^^^^^^^^^^^^^^^^^^^^^^^^^^^^^^^^^^
  File "/Users/chriswest/Desktop/ai_donkeys/.venv/lib/python3.11/site-packages/flask/views.py", line 110, in view
    return current_app.ensure_sync(self.dispatch_request)(**kwargs)  # type: ignore[no-any-return]
           ^^^^^^^^^^^^^^^^^^^^^^^^^^^^^^^^^^^^^^^^^^^^^^^^^^^^^^^^
  File "/Users/chriswest/Desktop/ai_donkeys/.venv/lib/python3.11/site-packages/flask/views.py", line 191, in dispatch_request
    return current_app.ensure_sync(meth)(**kwargs)  # type: ignore[no-any-return]
           ^^^^^^^^^^^^^^^^^^^^^^^^^^^^^^^^^^^^^^^
  File "/Users/chriswest/Desktop/ai_donkeys/.venv/lib/python3.11/site-packages/flask_jwt_extended/view_decorators.py", line 170, in decorator
    return current_app.ensure_sync(fn)(*args, **kwargs)
           ^^^^^^^^^^^^^^^^^^^^^^^^^^^^^^^^^^^^^^^^^^^^
  File "/Users/chriswest/Desktop/ai_donkeys/backend/routes/blogs.py", line 65, in post
    new_post.generate_slug()
  File "/Users/chriswest/Desktop/ai_donkeys/backend/models/blogs.py", line 58, in generate_slug
    slug = re.sub(r"\W+", "-", slug)
           ^^
NameError: name 're' is not defined
2024-03-20 10:14:39,548 INFO: PGVector extension enabled successfully. [in helper_functions.py:191]
2024-03-20 10:14:59,561 ERROR: Exception on /api/blog/posts [GET] [in app.py:828]
Traceback (most recent call last):
  File "/Users/chriswest/Desktop/ai_donkeys/.venv/lib/python3.11/site-packages/flask/app.py", line 1463, in wsgi_app
    response = self.full_dispatch_request()
               ^^^^^^^^^^^^^^^^^^^^^^^^^^^^
  File "/Users/chriswest/Desktop/ai_donkeys/.venv/lib/python3.11/site-packages/flask/app.py", line 872, in full_dispatch_request
    rv = self.handle_user_exception(e)
         ^^^^^^^^^^^^^^^^^^^^^^^^^^^^^
  File "/Users/chriswest/Desktop/ai_donkeys/.venv/lib/python3.11/site-packages/flask_cors/extension.py", line 176, in wrapped_function
    return cors_after_request(app.make_response(f(*args, **kwargs)))
                                                ^^^^^^^^^^^^^^^^^^
  File "/Users/chriswest/Desktop/ai_donkeys/.venv/lib/python3.11/site-packages/flask/app.py", line 870, in full_dispatch_request
    rv = self.dispatch_request()
         ^^^^^^^^^^^^^^^^^^^^^^^
  File "/Users/chriswest/Desktop/ai_donkeys/.venv/lib/python3.11/site-packages/flask/app.py", line 855, in dispatch_request
    return self.ensure_sync(self.view_functions[rule.endpoint])(**view_args)  # type: ignore[no-any-return]
           ^^^^^^^^^^^^^^^^^^^^^^^^^^^^^^^^^^^^^^^^^^^^^^^^^^^^^^^^^^^^^^^^^
  File "/Users/chriswest/Desktop/ai_donkeys/.venv/lib/python3.11/site-packages/flask/views.py", line 110, in view
    return current_app.ensure_sync(self.dispatch_request)(**kwargs)  # type: ignore[no-any-return]
           ^^^^^^^^^^^^^^^^^^^^^^^^^^^^^^^^^^^^^^^^^^^^^^^^^^^^^^^^
  File "/Users/chriswest/Desktop/ai_donkeys/.venv/lib/python3.11/site-packages/flask/views.py", line 191, in dispatch_request
    return current_app.ensure_sync(meth)(**kwargs)  # type: ignore[no-any-return]
           ^^^^^^^^^^^^^^^^^^^^^^^^^^^^^^^^^^^^^^^
  File "/Users/chriswest/Desktop/ai_donkeys/backend/routes/blogs.py", line 40, in get
    return jsonify([post.serialize() for post in posts]), 200
                   ^^^^^^^^^^^^^^^^^^^^^^^^^^^^^^^^^^^^
  File "/Users/chriswest/Desktop/ai_donkeys/backend/routes/blogs.py", line 40, in <listcomp>
    return jsonify([post.serialize() for post in posts]), 200
                    ^^^^^^^^^^^^^^
AttributeError: 'Post' object has no attribute 'serialize'
2024-03-20 10:15:49,981 INFO: PGVector extension enabled successfully. [in helper_functions.py:191]
2024-03-20 10:17:00,284 ERROR: Exception on /api/blog/posts [POST] [in app.py:828]
Traceback (most recent call last):
  File "/Users/chriswest/Desktop/ai_donkeys/.venv/lib/python3.11/site-packages/flask/app.py", line 1463, in wsgi_app
    response = self.full_dispatch_request()
               ^^^^^^^^^^^^^^^^^^^^^^^^^^^^
  File "/Users/chriswest/Desktop/ai_donkeys/.venv/lib/python3.11/site-packages/flask/app.py", line 872, in full_dispatch_request
    rv = self.handle_user_exception(e)
         ^^^^^^^^^^^^^^^^^^^^^^^^^^^^^
  File "/Users/chriswest/Desktop/ai_donkeys/.venv/lib/python3.11/site-packages/flask_cors/extension.py", line 176, in wrapped_function
    return cors_after_request(app.make_response(f(*args, **kwargs)))
                                                ^^^^^^^^^^^^^^^^^^
  File "/Users/chriswest/Desktop/ai_donkeys/.venv/lib/python3.11/site-packages/flask/app.py", line 870, in full_dispatch_request
    rv = self.dispatch_request()
         ^^^^^^^^^^^^^^^^^^^^^^^
  File "/Users/chriswest/Desktop/ai_donkeys/.venv/lib/python3.11/site-packages/flask/app.py", line 855, in dispatch_request
    return self.ensure_sync(self.view_functions[rule.endpoint])(**view_args)  # type: ignore[no-any-return]
           ^^^^^^^^^^^^^^^^^^^^^^^^^^^^^^^^^^^^^^^^^^^^^^^^^^^^^^^^^^^^^^^^^
  File "/Users/chriswest/Desktop/ai_donkeys/.venv/lib/python3.11/site-packages/flask/views.py", line 110, in view
    return current_app.ensure_sync(self.dispatch_request)(**kwargs)  # type: ignore[no-any-return]
           ^^^^^^^^^^^^^^^^^^^^^^^^^^^^^^^^^^^^^^^^^^^^^^^^^^^^^^^^
  File "/Users/chriswest/Desktop/ai_donkeys/.venv/lib/python3.11/site-packages/flask/views.py", line 191, in dispatch_request
    return current_app.ensure_sync(meth)(**kwargs)  # type: ignore[no-any-return]
           ^^^^^^^^^^^^^^^^^^^^^^^^^^^^^^^^^^^^^^^
  File "/Users/chriswest/Desktop/ai_donkeys/.venv/lib/python3.11/site-packages/flask_jwt_extended/view_decorators.py", line 170, in decorator
    return current_app.ensure_sync(fn)(*args, **kwargs)
           ^^^^^^^^^^^^^^^^^^^^^^^^^^^^^^^^^^^^^^^^^^^^
  File "/Users/chriswest/Desktop/ai_donkeys/backend/routes/blogs.py", line 54, in post
    validated_data, errors = hf.validate_data(post_schema, data)
                             ^^^^^^^^^^^^^^^^^^^^^^^^^^^^^^^^^^^
  File "/Users/chriswest/Desktop/ai_donkeys/backend/helpers/helper_functions.py", line 20, in validate_data
    return schema.load(data), None
           ^^^^^^^^^^^^^^^^^
  File "/Users/chriswest/Desktop/ai_donkeys/.venv/lib/python3.11/site-packages/marshmallow/schema.py", line 723, in load
    return self._do_load(
           ^^^^^^^^^^^^^^
  File "/Users/chriswest/Desktop/ai_donkeys/.venv/lib/python3.11/site-packages/marshmallow/schema.py", line 910, in _do_load
    raise exc
marshmallow.exceptions.ValidationError: {'categories': ['Not a valid list.']}
2024-03-20 10:17:43,901 ERROR: Exception on /api/blog/posts [POST] [in app.py:828]
Traceback (most recent call last):
  File "/Users/chriswest/Desktop/ai_donkeys/.venv/lib/python3.11/site-packages/flask/app.py", line 1463, in wsgi_app
    response = self.full_dispatch_request()
               ^^^^^^^^^^^^^^^^^^^^^^^^^^^^
  File "/Users/chriswest/Desktop/ai_donkeys/.venv/lib/python3.11/site-packages/flask/app.py", line 872, in full_dispatch_request
    rv = self.handle_user_exception(e)
         ^^^^^^^^^^^^^^^^^^^^^^^^^^^^^
  File "/Users/chriswest/Desktop/ai_donkeys/.venv/lib/python3.11/site-packages/flask_cors/extension.py", line 176, in wrapped_function
    return cors_after_request(app.make_response(f(*args, **kwargs)))
                                                ^^^^^^^^^^^^^^^^^^
  File "/Users/chriswest/Desktop/ai_donkeys/.venv/lib/python3.11/site-packages/flask/app.py", line 870, in full_dispatch_request
    rv = self.dispatch_request()
         ^^^^^^^^^^^^^^^^^^^^^^^
  File "/Users/chriswest/Desktop/ai_donkeys/.venv/lib/python3.11/site-packages/flask/app.py", line 855, in dispatch_request
    return self.ensure_sync(self.view_functions[rule.endpoint])(**view_args)  # type: ignore[no-any-return]
           ^^^^^^^^^^^^^^^^^^^^^^^^^^^^^^^^^^^^^^^^^^^^^^^^^^^^^^^^^^^^^^^^^
  File "/Users/chriswest/Desktop/ai_donkeys/.venv/lib/python3.11/site-packages/flask/views.py", line 110, in view
    return current_app.ensure_sync(self.dispatch_request)(**kwargs)  # type: ignore[no-any-return]
           ^^^^^^^^^^^^^^^^^^^^^^^^^^^^^^^^^^^^^^^^^^^^^^^^^^^^^^^^
  File "/Users/chriswest/Desktop/ai_donkeys/.venv/lib/python3.11/site-packages/flask/views.py", line 191, in dispatch_request
    return current_app.ensure_sync(meth)(**kwargs)  # type: ignore[no-any-return]
           ^^^^^^^^^^^^^^^^^^^^^^^^^^^^^^^^^^^^^^^
  File "/Users/chriswest/Desktop/ai_donkeys/.venv/lib/python3.11/site-packages/flask_jwt_extended/view_decorators.py", line 170, in decorator
    return current_app.ensure_sync(fn)(*args, **kwargs)
           ^^^^^^^^^^^^^^^^^^^^^^^^^^^^^^^^^^^^^^^^^^^^
  File "/Users/chriswest/Desktop/ai_donkeys/backend/routes/blogs.py", line 54, in post
    validated_data, errors = hf.validate_data(post_schema, data)
                             ^^^^^^^^^^^^^^^^^^^^^^^^^^^^^^^^^^^
  File "/Users/chriswest/Desktop/ai_donkeys/backend/helpers/helper_functions.py", line 20, in validate_data
    return schema.load(data), None
           ^^^^^^^^^^^^^^^^^
  File "/Users/chriswest/Desktop/ai_donkeys/.venv/lib/python3.11/site-packages/marshmallow/schema.py", line 723, in load
    return self._do_load(
           ^^^^^^^^^^^^^^
  File "/Users/chriswest/Desktop/ai_donkeys/.venv/lib/python3.11/site-packages/marshmallow/schema.py", line 910, in _do_load
    raise exc
marshmallow.exceptions.ValidationError: {'categories': ['Not a valid list.']}
2024-03-20 10:18:58,765 INFO: PGVector extension enabled successfully. [in helper_functions.py:191]
2024-03-20 10:20:41,790 ERROR: Exception on /api/blog/posts/creating-a-wolrd-with-ai-and-blockchain [PUT] [in app.py:828]
Traceback (most recent call last):
  File "/Users/chriswest/Desktop/ai_donkeys/.venv/lib/python3.11/site-packages/flask/app.py", line 1463, in wsgi_app
    response = self.full_dispatch_request()
               ^^^^^^^^^^^^^^^^^^^^^^^^^^^^
  File "/Users/chriswest/Desktop/ai_donkeys/.venv/lib/python3.11/site-packages/flask/app.py", line 872, in full_dispatch_request
    rv = self.handle_user_exception(e)
         ^^^^^^^^^^^^^^^^^^^^^^^^^^^^^
  File "/Users/chriswest/Desktop/ai_donkeys/.venv/lib/python3.11/site-packages/flask_cors/extension.py", line 176, in wrapped_function
    return cors_after_request(app.make_response(f(*args, **kwargs)))
                                                ^^^^^^^^^^^^^^^^^^
  File "/Users/chriswest/Desktop/ai_donkeys/.venv/lib/python3.11/site-packages/flask/app.py", line 870, in full_dispatch_request
    rv = self.dispatch_request()
         ^^^^^^^^^^^^^^^^^^^^^^^
  File "/Users/chriswest/Desktop/ai_donkeys/.venv/lib/python3.11/site-packages/flask/app.py", line 855, in dispatch_request
    return self.ensure_sync(self.view_functions[rule.endpoint])(**view_args)  # type: ignore[no-any-return]
           ^^^^^^^^^^^^^^^^^^^^^^^^^^^^^^^^^^^^^^^^^^^^^^^^^^^^^^^^^^^^^^^^^
  File "/Users/chriswest/Desktop/ai_donkeys/.venv/lib/python3.11/site-packages/flask/views.py", line 110, in view
    return current_app.ensure_sync(self.dispatch_request)(**kwargs)  # type: ignore[no-any-return]
           ^^^^^^^^^^^^^^^^^^^^^^^^^^^^^^^^^^^^^^^^^^^^^^^^^^^^^^^^
  File "/Users/chriswest/Desktop/ai_donkeys/.venv/lib/python3.11/site-packages/flask/views.py", line 191, in dispatch_request
    return current_app.ensure_sync(meth)(**kwargs)  # type: ignore[no-any-return]
           ^^^^^^^^^^^^^^^^^^^^^^^^^^^^^^^^^^^^^^^
  File "/Users/chriswest/Desktop/ai_donkeys/backend/routes/blogs.py", line 94, in put
    hf.update_db(post)
TypeError: update_db() takes 0 positional arguments but 1 was given
2024-03-20 10:21:22,620 INFO: PGVector extension enabled successfully. [in helper_functions.py:191]
